Workbook

Sheet Cover
B2: AI Act Register for HR
B3: Regulation (EU) 2024/1689 as amended by Regulation (EU) 2026/1744 - a dry run for an employer in four Member States
B5: What it does
C6: Lists every AI system the HR function uses and classifies it: prohibited, high-risk, not high-risk under Article 6(3), transparency only, or minimal risk.
C7: Says which obligations each system triggers and from when, including where building a system in-house makes the employer its provider.
C8: Says which national rules on informing and consulting workers apply in Italy, Germany, Spain and Poland.
B10: How to read it
B11: Blue text | C11: an input: an answer about a system, a date
B12: Black text | C12: a formula
B13: Green text | C13: a link to another sheet
B14: Yellow fill | C14: a key assumption that moves the results
B16: Sheets
B17: Summary | C17: Systems by class, the provider question, days to the high-risk duties, national rules.
B18: Register | C18: One row per AI system: the answers that decide its class, the class and why.
B19: Obligations | C19: Which of thirteen obligations each system triggers, with the article.
B20: Workers | C20: Which national rules on telling the workers each system triggers.
B21: Timeline | C21: The obligations in date order: what is already in force, what starts in December 2027.
B22: Headcount | C22: Workers by employer and department, to size each system's scope.
B23: Settings | C23: The application dates of the AI Act and the date of this assessment.
B24: Reconciliation | C24: Each workbook figure checked against the Python register.
B26: Check | C26: =Reconciliation!B3
B28: Limits | C28: Synthetic organisation and systems. Not legal advice. The classification follows the AI Act text; Commission guidelines and national practice can move boundary cases. Sources and their status are in docs/verification.md in the repository.
B30: Domenico Perroni | C30: https://github.com/D0M3N1C0X/ai-act-hr-readiness-kit

Sheet Summary
A1: AI Act readiness for HR: summary
A2: Dry run for an employer in four countries, 3,443 workers. Not legal advice.
B4: AI systems by class | E4: Telling the workers: systems per rule
B5: Prohibited | C5: =COUNTIF(Register!$W$5:$W$16,B5) | E5: W-IT1 · Information on fully automated decision or monitoring systems | F5: =Workers!D18
B6: High-risk | C6: =COUNTIF(Register!$W$5:$W$16,B6) | E6: W-IT2 · Agreement or authorisation for tools that allow remote monitoring | F6: =Workers!E18
B7: Not high-risk (Art. 6(3)) | C7: =COUNTIF(Register!$W$5:$W$16,B7) | E7: W-DE1 · Information and consultation on planned AI in work procedures | F7: =Workers!F18
B8: Transparency only | C8: =COUNTIF(Register!$W$5:$W$16,B8) | E8: W-DE2 · Co-determination on technical devices able to monitor conduct or performance | F8: =Workers!G18
B9: Minimal risk | C9: =COUNTIF(Register!$W$5:$W$16,B9) | E9: W-DE3 · Co-determination on selection guidelines | F9: =Workers!H18
E10: W-DE4 · An expert for the works council, deemed necessary for AI | F10: =Workers!I18
B11: Total | C11: =SUM(C5:C9) | E11: W-ES1 · Information on the parameters of algorithms affecting work | F11: =Workers!J18
B12: Systems the employer put into service itself and therefore provides (Art. 3(3)) | C12: =COUNTIF(Register!$X$5:$X$16,"Provider and deployer") | E12: W-PL1 · Notice of monitoring other than video | F12: =Workers!K18
B13: Days to the high-risk duties (2 December 2027) | C13: =Timeline!F19
B14: High-risk systems already on the market: duties at their next significant design change | C14: =COUNTIF(Register!$Y$5:$Y$16,"At its next significant design change")

Sheet Register
A1: Register: every AI system the HR function uses, and its class under the AI Act
A2: Blue columns are the answers about each system; the grey-headed columns are formulas. Change an answer and the system is reclassified.
A4: ID | B4: AI system | C4: HR function | D4: Supplier | E4: Department in scope | F4: Used in IT | G4: Used in PL | H4: Used in DE | I4: Used in ES | J4: Used on applicants | K4: Infers emotions | L4: For medical or safety reasons | M4: Annex III point 4 | N4: Profiles people | O4: Art. 6(3) condition | P4: Talks to people | Q4: Decides or helps decide about people | R4: Fully automated | S4: Monitors workers | T4: Employer controls the input data | U4: Type and model on the market before 2 Dec 2027 | V4: Workers in scope | W4: Class | X4: Role | Y4: High-risk duties apply | Z4: Why
A5: S01 | B5: CV screening and ranking | C5: Recruitment | D5: Vendor | E5: All | F5: Yes | G5: Yes | H5: Yes | I5: Yes | J5: Yes | K5: No | L5: No | M5: 4(a) | N5: Yes | O5: None | P5: No | Q5: Yes | R5: No | S5: No | T5: Yes | U5: Yes | V5: =SUMPRODUCT(Headcount!$C$5:$C$28*((Headcount!$A$5:$A$28="IT")*($F5="Yes")+(Headcount!$A$5:$A$28="PL")*($G5="Yes")+(Headcount!$A$5:$A$28="DE")*($H5="Yes")+(Headcount!$A$5:$A$28="ES")*($I5="Yes"))*((($E5="All")+(Headcount!$B$5:$B$28=$E5))>0)) | W5: =IF(AND($K5="Yes",$L5<>"Yes"),"Prohibited",IF($M5<>"None",IF($N5="Yes","High-risk",IF($O5<>"None","Not high-risk (Art. 6(3))","High-risk")),IF($P5="Yes","Transparency only","Minimal risk"))) | X5: =IF(AND($D5="In-house",$W5="High-risk"),"Provider and deployer","Deployer") | Y5: =IF($W5<>"High-risk","",IF($U5="Yes","At its next significant design change","From 2 December 2027")) | Z5: Scores and ranks every application against the vacancy; recruiters see the ranked list first. Filtering applications is named in Annex III 4(a), and ranking people on their profile is profiling, so the Article 6(3) derogation cannot apply.
A6: S02 | B6: Targeted job advertising | C6: Recruitment | D6: Vendor | E6: All | F6: Yes | G6: Yes | H6: Yes | I6: Yes | J6: Yes | K6: No | L6: No | M6: 4(a) | N6: Yes | O6: None | P6: No | Q6: No | R6: Yes | S6: No | T6: Yes | U6: Yes | V6: =SUMPRODUCT(Headcount!$C$5:$C$28*((Headcount!$A$5:$A$28="IT")*($F6="Yes")+(Headcount!$A$5:$A$28="PL")*($G6="Yes")+(Headcount!$A$5:$A$28="DE")*($H6="Yes")+(Headcount!$A$5:$A$28="ES")*($I6="Yes"))*((($E6="All")+(Headcount!$B$5:$B$28=$E6))>0)) | W6: =IF(AND($K6="Yes",$L6<>"Yes"),"Prohibited",IF($M6<>"None",IF($N6="Yes","High-risk",IF($O6<>"None","Not high-risk (Art. 6(3))","High-risk")),IF($P6="Yes","Transparency only","Minimal risk"))) | X6: =IF(AND($D6="In-house",$W6="High-risk"),"Provider and deployer","Deployer") | Y6: =IF($W6<>"High-risk","",IF($U6="Yes","At its next significant design change","From 2 December 2027")) | Z6: The job board decides who sees each advert from users' profiles, with no one reviewing who is shown it. Placing targeted job advertisements is named in Annex III 4(a); the employer chooses the audience settings, so it controls part of the input.
A7: S03 | B7: Video interview analysis | C7: Recruitment | D7: Vendor | E7: All | F7: No | G7: No | H7: No | I7: Yes | J7: Yes | K7: Yes | L7: No | M7: 4(a) | N7: Yes | O7: None | P7: No | Q7: Yes | R7: No | S7: No | T7: No | U7: Yes | V7: =SUMPRODUCT(Headcount!$C$5:$C$28*((Headcount!$A$5:$A$28="IT")*($F7="Yes")+(Headcount!$A$5:$A$28="PL")*($G7="Yes")+(Headcount!$A$5:$A$28="DE")*($H7="Yes")+(Headcount!$A$5:$A$28="ES")*($I7="Yes"))*((($E7="All")+(Headcount!$B$5:$B$28=$E7))>0)) | W7: =IF(AND($K7="Yes",$L7<>"Yes"),"Prohibited",IF($M7<>"None",IF($N7="Yes","High-risk",IF($O7<>"None","Not high-risk (Art. 6(3))","High-risk")),IF($P7="Yes","Transparency only","Minimal risk"))) | X7: =IF(AND($D7="In-house",$W7="High-risk"),"Provider and deployer","Deployer") | Y7: =IF($W7<>"High-risk","",IF($U7="Yes","At its next significant design change","From 2 December 2027")) | Z7: A pilot in Barcelona scores recorded interviews on tone of voice and facial expressions. Inferring emotions in the workplace is prohibited unless for medical or safety reasons, and candidates in a selection process fall within it: the use has to stop.
A8: S04 | B8: Interview scheduling assistant | C8: Recruitment | D8: Vendor | E8: All | F8: Yes | G8: Yes | H8: Yes | I8: Yes | J8: Yes | K8: No | L8: No | M8: 4(a) | N8: No | O8: (a) | P8: Yes | Q8: No | R8: No | S8: No | T8: No | U8: Yes | V8: =SUMPRODUCT(Headcount!$C$5:$C$28*((Headcount!$A$5:$A$28="IT")*($F8="Yes")+(Headcount!$A$5:$A$28="PL")*($G8="Yes")+(Headcount!$A$5:$A$28="DE")*($H8="Yes")+(Headcount!$A$5:$A$28="ES")*($I8="Yes"))*((($E8="All")+(Headcount!$B$5:$B$28=$E8))>0)) | W8: =IF(AND($K8="Yes",$L8<>"Yes"),"Prohibited",IF($M8<>"None",IF($N8="Yes","High-risk",IF($O8<>"None","Not high-risk (Art. 6(3))","High-risk")),IF($P8="Yes","Transparency only","Minimal risk"))) | X8: =IF(AND($D8="In-house",$W8="High-risk"),"Provider and deployer","Deployer") | Y8: =IF($W8<>"High-risk","",IF($U8="Yes","At its next significant design change","From 2 December 2027")) | Z8: Proposes interview slots from calendars once a recruiter has shortlisted a candidate. Part of a recruitment process, but a narrow procedural task that profiles no one: Article 6(3)(a). It talks to candidates by email, so Article 50(1) applies to its provider.
A9: S05 | B9: Customer service performance analytics | C9: Performance | D9: Vendor | E9: Customer Service | F9: Yes | G9: Yes | H9: Yes | I9: Yes | J9: No | K9: No | L9: No | M9: 4(b) | N9: Yes | O9: None | P9: No | Q9: Yes | R9: No | S9: Yes | T9: Yes | U9: Yes | V9: =SUMPRODUCT(Headcount!$C$5:$C$28*((Headcount!$A$5:$A$28="IT")*($F9="Yes")+(Headcount!$A$5:$A$28="PL")*($G9="Yes")+(Headcount!$A$5:$A$28="DE")*($H9="Yes")+(Headcount!$A$5:$A$28="ES")*($I9="Yes"))*((($E9="All")+(Headcount!$B$5:$B$28=$E9))>0)) | W9: =IF(AND($K9="Yes",$L9<>"Yes"),"Prohibited",IF($M9<>"None",IF($N9="Yes","High-risk",IF($O9<>"None","Not high-risk (Art. 6(3))","High-risk")),IF($P9="Yes","Transparency only","Minimal risk"))) | X9: =IF(AND($D9="In-house",$W9="High-risk"),"Provider and deployer","Deployer") | Y9: =IF($W9<>"High-risk","",IF($U9="Yes","At its next significant design change","From 2 December 2027")) | Z9: Scores each agent weekly on handling time, resolution and sentiment of the customer's words, and flags low performers to team leads. Monitoring and evaluating performance is named in Annex III 4(b); scoring individuals is profiling.
A10: S06 | B10: Shift scheduling optimiser | C10: Workforce planning | D10: Vendor | E10: Operations | F10: Yes | G10: Yes | H10: Yes | I10: Yes | J10: No | K10: No | L10: No | M10: 4(b) | N10: Yes | O10: None | P10: No | Q10: Yes | R10: Yes | S10: No | T10: Yes | U10: Yes | V10: =SUMPRODUCT(Headcount!$C$5:$C$28*((Headcount!$A$5:$A$28="IT")*($F10="Yes")+(Headcount!$A$5:$A$28="PL")*($G10="Yes")+(Headcount!$A$5:$A$28="DE")*($H10="Yes")+(Headcount!$A$5:$A$28="ES")*($I10="Yes"))*((($E10="All")+(Headcount!$B$5:$B$28=$E10))>0)) | W10: =IF(AND($K10="Yes",$L10<>"Yes"),"Prohibited",IF($M10<>"None",IF($N10="Yes","High-risk",IF($O10<>"None","Not high-risk (Art. 6(3))","High-risk")),IF($P10="Yes","Transparency only","Minimal risk"))) | X10: =IF(AND($D10="In-house",$W10="High-risk"),"Provider and deployer","Deployer") | Y10: =IF($W10<>"High-risk","",IF($U10="Yes","At its next significant design change","From 2 December 2027")) | Z10: Allocates shifts in the warehouses from each worker's certified skills, availability and past attendance, and publishes the rota unless a supervisor steps in. Allocating tasks on individual behaviour or characteristics is named in Annex III 4(b), and past attendance makes it profiling. A boundary case: on availability alone it might not be.
A11: S07 | B11: Attrition-risk model | C11: Retention | D11: In-house | E11: All | F11: Yes | G11: Yes | H11: Yes | I11: Yes | J11: No | K11: No | L11: No | M11: 4(b) | N11: Yes | O11: None | P11: No | Q11: Yes | R11: No | S11: No | T11: Yes | U11: Yes | V11: =SUMPRODUCT(Headcount!$C$5:$C$28*((Headcount!$A$5:$A$28="IT")*($F11="Yes")+(Headcount!$A$5:$A$28="PL")*($G11="Yes")+(Headcount!$A$5:$A$28="DE")*($H11="Yes")+(Headcount!$A$5:$A$28="ES")*($I11="Yes"))*((($E11="All")+(Headcount!$B$5:$B$28=$E11))>0)) | W11: =IF(AND($K11="Yes",$L11<>"Yes"),"Prohibited",IF($M11<>"None",IF($N11="Yes","High-risk",IF($O11<>"None","Not high-risk (Art. 6(3))","High-risk")),IF($P11="Yes","Transparency only","Minimal risk"))) | X11: =IF(AND($D11="In-house",$W11="High-risk"),"Provider and deployer","Deployer") | Y11: =IF($W11<>"High-risk","",IF($U11="Yes","At its next significant design change","From 2 December 2027")) | Z11: Built by HR analytics on the people data (see hr-people-analytics): a risk score per employee that managers use to plan retention conversations and counter-offers. It evaluates individuals and shapes decisions on terms of work, so it is high-risk, and because the employer put it into service for its own use, the employer is its provider (Art. 3(3) and (11)).
A12: S08 | B12: Pay review recommender | C12: Reward | D12: Vendor | E12: All | F12: Yes | G12: Yes | H12: Yes | I12: Yes | J12: No | K12: No | L12: No | M12: 4(b) | N12: Yes | O12: None | P12: No | Q12: Yes | R12: No | S12: No | T12: Yes | U12: Yes | V12: =SUMPRODUCT(Headcount!$C$5:$C$28*((Headcount!$A$5:$A$28="IT")*($F12="Yes")+(Headcount!$A$5:$A$28="PL")*($G12="Yes")+(Headcount!$A$5:$A$28="DE")*($H12="Yes")+(Headcount!$A$5:$A$28="ES")*($I12="Yes"))*((($E12="All")+(Headcount!$B$5:$B$28=$E12))>0)) | W12: =IF(AND($K12="Yes",$L12<>"Yes"),"Prohibited",IF($M12<>"None",IF($N12="Yes","High-risk",IF($O12<>"None","Not high-risk (Art. 6(3))","High-risk")),IF($P12="Yes","Transparency only","Minimal risk"))) | X12: =IF(AND($D12="In-house",$W12="High-risk"),"Provider and deployer","Deployer") | Y12: =IF($W12<>"High-risk","",IF($U12="Yes","At its next significant design change","From 2 December 2027")) | Z12: The compensation module proposes each employee's merit increase from rating, compa-ratio and market data; managers accept or edit. Decisions affecting terms of work-related relationships are named in Annex III 4(b). Its pay-setting criteria must also be objective and gender-neutral under the Pay Transparency Directive (Articles 4(4) and 6(1)).
A13: S09 | B13: HR service chatbot | C13: HR service | D13: Vendor | E13: All | F13: Yes | G13: Yes | H13: Yes | I13: Yes | J13: No | K13: No | L13: No | M13: None | N13: No | O13: None | P13: Yes | Q13: No | R13: No | S13: No | T13: No | U13: Yes | V13: =SUMPRODUCT(Headcount!$C$5:$C$28*((Headcount!$A$5:$A$28="IT")*($F13="Yes")+(Headcount!$A$5:$A$28="PL")*($G13="Yes")+(Headcount!$A$5:$A$28="DE")*($H13="Yes")+(Headcount!$A$5:$A$28="ES")*($I13="Yes"))*((($E13="All")+(Headcount!$B$5:$B$28=$E13))>0)) | W13: =IF(AND($K13="Yes",$L13<>"Yes"),"Prohibited",IF($M13<>"None",IF($N13="Yes","High-risk",IF($O13<>"None","Not high-risk (Art. 6(3))","High-risk")),IF($P13="Yes","Transparency only","Minimal risk"))) | X13: =IF(AND($D13="In-house",$W13="High-risk"),"Provider and deployer","Deployer") | Y13: =IF($W13<>"High-risk","",IF($U13="Yes","At its next significant design change","From 2 December 2027")) | Z13: Answers employees' questions on leave, payroll and policies from the knowledge base, and hands over to an HR advisor. It decides nothing about anyone, so it is not in Annex III; people must know they are talking to an AI (Article 50(1)).
A14: S10 | B14: Learning recommendations | C14: Learning | D14: Vendor | E14: All | F14: Yes | G14: Yes | H14: Yes | I14: Yes | J14: No | K14: No | L14: No | M14: None | N14: No | O14: None | P14: No | Q14: No | R14: No | S14: No | T14: No | U14: Yes | V14: =SUMPRODUCT(Headcount!$C$5:$C$28*((Headcount!$A$5:$A$28="IT")*($F14="Yes")+(Headcount!$A$5:$A$28="PL")*($G14="Yes")+(Headcount!$A$5:$A$28="DE")*($H14="Yes")+(Headcount!$A$5:$A$28="ES")*($I14="Yes"))*((($E14="All")+(Headcount!$B$5:$B$28=$E14))>0)) | W14: =IF(AND($K14="Yes",$L14<>"Yes"),"Prohibited",IF($M14<>"None",IF($N14="Yes","High-risk",IF($O14<>"None","Not high-risk (Art. 6(3))","High-risk")),IF($P14="Yes","Transparency only","Minimal risk"))) | X14: =IF(AND($D14="In-house",$W14="High-risk"),"Provider and deployer","Deployer") | Y14: =IF($W14<>"High-risk","",IF($U14="Yes","At its next significant design change","From 2 December 2027")) | Z14: Suggests courses from role and past courses. Annex III point 3 covers education and vocational training institutions, not an employer's course suggestions; completion has no bearing on promotion or pay in this organisation. If it did, the system would move into Annex III 4(b).
A15: S11 | B15: Writing and translation assistant | C15: HR service | D15: Vendor | E15: HR | F15: Yes | G15: Yes | H15: Yes | I15: Yes | J15: No | K15: No | L15: No | M15: None | N15: No | O15: None | P15: No | Q15: No | R15: No | S15: No | T15: No | U15: Yes | V15: =SUMPRODUCT(Headcount!$C$5:$C$28*((Headcount!$A$5:$A$28="IT")*($F15="Yes")+(Headcount!$A$5:$A$28="PL")*($G15="Yes")+(Headcount!$A$5:$A$28="DE")*($H15="Yes")+(Headcount!$A$5:$A$28="ES")*($I15="Yes"))*((($E15="All")+(Headcount!$B$5:$B$28=$E15))>0)) | W15: =IF(AND($K15="Yes",$L15<>"Yes"),"Prohibited",IF($M15<>"None",IF($N15="Yes","High-risk",IF($O15<>"None","Not high-risk (Art. 6(3))","High-risk")),IF($P15="Yes","Transparency only","Minimal risk"))) | X15: =IF(AND($D15="In-house",$W15="High-risk"),"Provider and deployer","Deployer") | Y15: =IF($W15<>"High-risk","",IF($U15="Yes","At its next significant design change","From 2 December 2027")) | Z15: A general-purpose assistant HR staff use to draft and translate letters and policies, reviewed before sending. Minimal risk; the staff who use it are within the AI literacy duty.
A16: S12 | B16: Internal mobility matching | C16: Talent | D16: Vendor | E16: All | F16: Yes | G16: Yes | H16: Yes | I16: Yes | J16: No | K16: No | L16: No | M16: 4(a) | N16: Yes | O16: None | P16: No | Q16: Yes | R16: No | S16: No | T16: Yes | U16: Yes | V16: =SUMPRODUCT(Headcount!$C$5:$C$28*((Headcount!$A$5:$A$28="IT")*($F16="Yes")+(Headcount!$A$5:$A$28="PL")*($G16="Yes")+(Headcount!$A$5:$A$28="DE")*($H16="Yes")+(Headcount!$A$5:$A$28="ES")*($I16="Yes"))*((($E16="All")+(Headcount!$B$5:$B$28=$E16))>0)) | W16: =IF(AND($K16="Yes",$L16<>"Yes"),"Prohibited",IF($M16<>"None",IF($N16="Yes","High-risk",IF($O16<>"None","Not high-risk (Art. 6(3))","High-risk")),IF($P16="Yes","Transparency only","Minimal risk"))) | X16: =IF(AND($D16="In-house",$W16="High-risk"),"Provider and deployer","Deployer") | Y16: =IF($W16<>"High-risk","",IF($U16="Yes","At its next significant design change","From 2 December 2027")) | Z16: Matches employees to internal vacancies and ranks internal candidates for the hiring manager. Selection is named in Annex III 4(a), and ranking people on their profile is profiling.

Sheet Obligations
A1: Obligations: what each system triggers, and from when
A2: Row 5 gives the article. The Timeline sheet puts the obligations in date order.
A4: ID | B4: AI system | C4: Class | D4: O01 AI literacy of the staff who operate or use it | E4: O02 Stop the prohibited use | F4: O03 People told they are talking to an AI: the supplier's duty, checked by the employer | G4: O04 Use as instructed, with named human oversight | H4: O05 Input data relevant and representative | I4: O06 Monitor; report risks and serious incidents; suspend | J4: O07 Keep the logs for at least six months | K4: O08 Tell workers' representatives and affected workers before use | L4: O09 Data protection impact assessment built on the provider's information | M4: O10 Tell the people decisions are made about | N4: O11 Explain a decision on request | O4: O12 Provider duties for a system built in-house | P4: O13 Not-high-risk assessment documented
D5: Art. 4 | E5: Art. 5(1)(f) | F5: Art. 50(1) | G5: Art. 26(1)-(2) | H5: Art. 26(4) | I5: Art. 26(5) | J5: Art. 26(6) | K5: Art. 26(7) | L5: Art. 26(9); GDPR Art. 35 | M5: Art. 26(11) | N5: Art. 86 | O5: Art. 3(3), 16 | P5: Art. 6(4)
A6: =Register!A5 | B6: =Register!B5 | C6: =Register!$W$5 | D6: =IF(Register!$W$5<>"Prohibited","Yes","") | E6: =IF(Register!$W$5="Prohibited","Yes","") | F6: =IF(AND(Register!$P$5="Yes",Register!$W$5<>"Prohibited"),"Yes","") | G6: =IF(Register!$W$5="High-risk","Yes","") | H6: =IF(AND(Register!$W$5="High-risk",Register!$T$5="Yes"),"Yes","") | I6: =IF(Register!$W$5="High-risk","Yes","") | J6: =IF(Register!$W$5="High-risk","Yes","") | K6: =IF(AND(Register!$W$5="High-risk",Register!$J$5<>"Yes"),"Yes","") | L6: =IF(Register!$W$5="High-risk","Yes","") | M6: =IF(AND(Register!$W$5="High-risk",Register!$Q$5="Yes"),"Yes","") | N6: =IF(AND(Register!$W$5="High-risk",Register!$Q$5="Yes"),"Yes","") | O6: =IF(AND(Register!$W$5="High-risk",Register!$D$5="In-house"),"Yes","") | P6: =IF(Register!$W$5="Not high-risk (Art. 6(3))","Yes","")
A7: =Register!A6 | B7: =Register!B6 | C7: =Register!$W$6 | D7: =IF(Register!$W$6<>"Prohibited","Yes","") | E7: =IF(Register!$W$6="Prohibited","Yes","") | F7: =IF(AND(Register!$P$6="Yes",Register!$W$6<>"Prohibited"),"Yes","") | G7: =IF(Register!$W$6="High-risk","Yes","") | H7: =IF(AND(Register!$W$6="High-risk",Register!$T$6="Yes"),"Yes","") | I7: =IF(Register!$W$6="High-risk","Yes","") | J7: =IF(Register!$W$6="High-risk","Yes","") | K7: =IF(AND(Register!$W$6="High-risk",Register!$J$6<>"Yes"),"Yes","") | L7: =IF(Register!$W$6="High-risk","Yes","") | M7: =IF(AND(Register!$W$6="High-risk",Register!$Q$6="Yes"),"Yes","") | N7: =IF(AND(Register!$W$6="High-risk",Register!$Q$6="Yes"),"Yes","") | O7: =IF(AND(Register!$W$6="High-risk",Register!$D$6="In-house"),"Yes","") | P7: =IF(Register!$W$6="Not high-risk (Art. 6(3))","Yes","")
A8: =Register!A7 | B8: =Register!B7 | C8: =Register!$W$7 | D8: =IF(Register!$W$7<>"Prohibited","Yes","") | E8: =IF(Register!$W$7="Prohibited","Yes","") | F8: =IF(AND(Register!$P$7="Yes",Register!$W$7<>"Prohibited"),"Yes","") | G8: =IF(Register!$W$7="High-risk","Yes","") | H8: =IF(AND(Register!$W$7="High-risk",Register!$T$7="Yes"),"Yes","") | I8: =IF(Register!$W$7="High-risk","Yes","") | J8: =IF(Register!$W$7="High-risk","Yes","") | K8: =IF(AND(Register!$W$7="High-risk",Register!$J$7<>"Yes"),"Yes","") | L8: =IF(Register!$W$7="High-risk","Yes","") | M8: =IF(AND(Register!$W$7="High-risk",Register!$Q$7="Yes"),"Yes","") | N8: =IF(AND(Register!$W$7="High-risk",Register!$Q$7="Yes"),"Yes","") | O8: =IF(AND(Register!$W$7="High-risk",Register!$D$7="In-house"),"Yes","") | P8: =IF(Register!$W$7="Not high-risk (Art. 6(3))","Yes","")
A9: =Register!A8 | B9: =Register!B8 | C9: =Register!$W$8 | D9: =IF(Register!$W$8<>"Prohibited","Yes","") | E9: =IF(Register!$W$8="Prohibited","Yes","") | F9: =IF(AND(Register!$P$8="Yes",Register!$W$8<>"Prohibited"),"Yes","") | G9: =IF(Register!$W$8="High-risk","Yes","") | H9: =IF(AND(Register!$W$8="High-risk",Register!$T$8="Yes"),"Yes","") | I9: =IF(Register!$W$8="High-risk","Yes","") | J9: =IF(Register!$W$8="High-risk","Yes","") | K9: =IF(AND(Register!$W$8="High-risk",Register!$J$8<>"Yes"),"Yes","") | L9: =IF(Register!$W$8="High-risk","Yes","") | M9: =IF(AND(Register!$W$8="High-risk",Register!$Q$8="Yes"),"Yes","") | N9: =IF(AND(Register!$W$8="High-risk",Register!$Q$8="Yes"),"Yes","") | O9: =IF(AND(Register!$W$8="High-risk",Register!$D$8="In-house"),"Yes","") | P9: =IF(Register!$W$8="Not high-risk (Art. 6(3))","Yes","")
A10: =Register!A9 | B10: =Register!B9 | C10: =Register!$W$9 | D10: =IF(Register!$W$9<>"Prohibited","Yes","") | E10: =IF(Register!$W$9="Prohibited","Yes","") | F10: =IF(AND(Register!$P$9="Yes",Register!$W$9<>"Prohibited"),"Yes","") | G10: =IF(Register!$W$9="High-risk","Yes","") | H10: =IF(AND(Register!$W$9="High-risk",Register!$T$9="Yes"),"Yes","") | I10: =IF(Register!$W$9="High-risk","Yes","") | J10: =IF(Register!$W$9="High-risk","Yes","") | K10: =IF(AND(Register!$W$9="High-risk",Register!$J$9<>"Yes"),"Yes","") | L10: =IF(Register!$W$9="High-risk","Yes","") | M10: =IF(AND(Register!$W$9="High-risk",Register!$Q$9="Yes"),"Yes","") | N10: =IF(AND(Register!$W$9="High-risk",Register!$Q$9="Yes"),"Yes","") | O10: =IF(AND(Register!$W$9="High-risk",Register!$D$9="In-house"),"Yes","") | P10: =IF(Register!$W$9="Not high-risk (Art. 6(3))","Yes","")
A11: =Register!A10 | B11: =Register!B10 | C11: =Register!$W$10 | D11: =IF(Register!$W$10<>"Prohibited","Yes","") | E11: =IF(Register!$W$10="Prohibited","Yes","") | F11: =IF(AND(Register!$P$10="Yes",Register!$W$10<>"Prohibited"),"Yes","") | G11: =IF(Register!$W$10="High-risk","Yes","") | H11: =IF(AND(Register!$W$10="High-risk",Register!$T$10="Yes"),"Yes","") | I11: =IF(Register!$W$10="High-risk","Yes","") | J11: =IF(Register!$W$10="High-risk","Yes","") | K11: =IF(AND(Register!$W$10="High-risk",Register!$J$10<>"Yes"),"Yes","") | L11: =IF(Register!$W$10="High-risk","Yes","") | M11: =IF(AND(Register!$W$10="High-risk",Register!$Q$10="Yes"),"Yes","") | N11: =IF(AND(Register!$W$10="High-risk",Register!$Q$10="Yes"),"Yes","") | O11: =IF(AND(Register!$W$10="High-risk",Register!$D$10="In-house"),"Yes","") | P11: =IF(Register!$W$10="Not high-risk (Art. 6(3))","Yes","")
A12: =Register!A11 | B12: =Register!B11 | C12: =Register!$W$11 | D12: =IF(Register!$W$11<>"Prohibited","Yes","") | E12: =IF(Register!$W$11="Prohibited","Yes","") | F12: =IF(AND(Register!$P$11="Yes",Register!$W$11<>"Prohibited"),"Yes","") | G12: =IF(Register!$W$11="High-risk","Yes","") | H12: =IF(AND(Register!$W$11="High-risk",Register!$T$11="Yes"),"Yes","") | I12: =IF(Register!$W$11="High-risk","Yes","") | J12: =IF(Register!$W$11="High-risk","Yes","") | K12: =IF(AND(Register!$W$11="High-risk",Register!$J$11<>"Yes"),"Yes","") | L12: =IF(Register!$W$11="High-risk","Yes","") | M12: =IF(AND(Register!$W$11="High-risk",Register!$Q$11="Yes"),"Yes","") | N12: =IF(AND(Register!$W$11="High-risk",Register!$Q$11="Yes"),"Yes","") | O12: =IF(AND(Register!$W$11="High-risk",Register!$D$11="In-house"),"Yes","") | P12: =IF(Register!$W$11="Not high-risk (Art. 6(3))","Yes","")
A13: =Register!A12 | B13: =Register!B12 | C13: =Register!$W$12 | D13: =IF(Register!$W$12<>"Prohibited","Yes","") | E13: =IF(Register!$W$12="Prohibited","Yes","") | F13: =IF(AND(Register!$P$12="Yes",Register!$W$12<>"Prohibited"),"Yes","") | G13: =IF(Register!$W$12="High-risk","Yes","") | H13: =IF(AND(Register!$W$12="High-risk",Register!$T$12="Yes"),"Yes","") | I13: =IF(Register!$W$12="High-risk","Yes","") | J13: =IF(Register!$W$12="High-risk","Yes","") | K13: =IF(AND(Register!$W$12="High-risk",Register!$J$12<>"Yes"),"Yes","") | L13: =IF(Register!$W$12="High-risk","Yes","") | M13: =IF(AND(Register!$W$12="High-risk",Register!$Q$12="Yes"),"Yes","") | N13: =IF(AND(Register!$W$12="High-risk",Register!$Q$12="Yes"),"Yes","") | O13: =IF(AND(Register!$W$12="High-risk",Register!$D$12="In-house"),"Yes","") | P13: =IF(Register!$W$12="Not high-risk (Art. 6(3))","Yes","")
A14: =Register!A13 | B14: =Register!B13 | C14: =Register!$W$13 | D14: =IF(Register!$W$13<>"Prohibited","Yes","") | E14: =IF(Register!$W$13="Prohibited","Yes","") | F14: =IF(AND(Register!$P$13="Yes",Register!$W$13<>"Prohibited"),"Yes","") | G14: =IF(Register!$W$13="High-risk","Yes","") | H14: =IF(AND(Register!$W$13="High-risk",Register!$T$13="Yes"),"Yes","") | I14: =IF(Register!$W$13="High-risk","Yes","") | J14: =IF(Register!$W$13="High-risk","Yes","") | K14: =IF(AND(Register!$W$13="High-risk",Register!$J$13<>"Yes"),"Yes","") | L14: =IF(Register!$W$13="High-risk","Yes","") | M14: =IF(AND(Register!$W$13="High-risk",Register!$Q$13="Yes"),"Yes","") | N14: =IF(AND(Register!$W$13="High-risk",Register!$Q$13="Yes"),"Yes","") | O14: =IF(AND(Register!$W$13="High-risk",Register!$D$13="In-house"),"Yes","") | P14: =IF(Register!$W$13="Not high-risk (Art. 6(3))","Yes","")
A15: =Register!A14 | B15: =Register!B14 | C15: =Register!$W$14 | D15: =IF(Register!$W$14<>"Prohibited","Yes","") | E15: =IF(Register!$W$14="Prohibited","Yes","") | F15: =IF(AND(Register!$P$14="Yes",Register!$W$14<>"Prohibited"),"Yes","") | G15: =IF(Register!$W$14="High-risk","Yes","") | H15: =IF(AND(Register!$W$14="High-risk",Register!$T$14="Yes"),"Yes","") | I15: =IF(Register!$W$14="High-risk","Yes","") | J15: =IF(Register!$W$14="High-risk","Yes","") | K15: =IF(AND(Register!$W$14="High-risk",Register!$J$14<>"Yes"),"Yes","") | L15: =IF(Register!$W$14="High-risk","Yes","") | M15: =IF(AND(Register!$W$14="High-risk",Register!$Q$14="Yes"),"Yes","") | N15: =IF(AND(Register!$W$14="High-risk",Register!$Q$14="Yes"),"Yes","") | O15: =IF(AND(Register!$W$14="High-risk",Register!$D$14="In-house"),"Yes","") | P15: =IF(Register!$W$14="Not high-risk (Art. 6(3))","Yes","")
A16: =Register!A15 | B16: =Register!B15 | C16: =Register!$W$15 | D16: =IF(Register!$W$15<>"Prohibited","Yes","") | E16: =IF(Register!$W$15="Prohibited","Yes","") | F16: =IF(AND(Register!$P$15="Yes",Register!$W$15<>"Prohibited"),"Yes","") | G16: =IF(Register!$W$15="High-risk","Yes","") | H16: =IF(AND(Register!$W$15="High-risk",Register!$T$15="Yes"),"Yes","") | I16: =IF(Register!$W$15="High-risk","Yes","") | J16: =IF(Register!$W$15="High-risk","Yes","") | K16: =IF(AND(Register!$W$15="High-risk",Register!$J$15<>"Yes"),"Yes","") | L16: =IF(Register!$W$15="High-risk","Yes","") | M16: =IF(AND(Register!$W$15="High-risk",Register!$Q$15="Yes"),"Yes","") | N16: =IF(AND(Register!$W$15="High-risk",Register!$Q$15="Yes"),"Yes","") | O16: =IF(AND(Register!$W$15="High-risk",Register!$D$15="In-house"),"Yes","") | P16: =IF(Register!$W$15="Not high-risk (Art. 6(3))","Yes","")
A17: =Register!A16 | B17: =Register!B16 | C17: =Register!$W$16 | D17: =IF(Register!$W$16<>"Prohibited","Yes","") | E17: =IF(Register!$W$16="Prohibited","Yes","") | F17: =IF(AND(Register!$P$16="Yes",Register!$W$16<>"Prohibited"),"Yes","") | G17: =IF(Register!$W$16="High-risk","Yes","") | H17: =IF(AND(Register!$W$16="High-risk",Register!$T$16="Yes"),"Yes","") | I17: =IF(Register!$W$16="High-risk","Yes","") | J17: =IF(Register!$W$16="High-risk","Yes","") | K17: =IF(AND(Register!$W$16="High-risk",Register!$J$16<>"Yes"),"Yes","") | L17: =IF(Register!$W$16="High-risk","Yes","") | M17: =IF(AND(Register!$W$16="High-risk",Register!$Q$16="Yes"),"Yes","") | N17: =IF(AND(Register!$W$16="High-risk",Register!$Q$16="Yes"),"Yes","") | O17: =IF(AND(Register!$W$16="High-risk",Register!$D$16="In-house"),"Yes","") | P17: =IF(Register!$W$16="Not high-risk (Art. 6(3))","Yes","")
B18: Systems | D18: =COUNTIF(D6:D17,"Yes") | E18: =COUNTIF(E6:E17,"Yes") | F18: =COUNTIF(F6:F17,"Yes") | G18: =COUNTIF(G6:G17,"Yes") | H18: =COUNTIF(H6:H17,"Yes") | I18: =COUNTIF(I6:I17,"Yes") | J18: =COUNTIF(J6:J17,"Yes") | K18: =COUNTIF(K6:K17,"Yes") | ... P18: =COUNTIF(P6:P17,"Yes")
B20: Considered and not applicable
B21: Fundamental rights impact assessment | C21: Art. 27 | D21: Owed by public bodies, private entities providing public services, and deployers of credit and insurance systems (Annex III 5(b)-(c)). A private employer using HR systems is none of these.
B22: Registration of the use in the EU database | C22: Art. 26(8), 49(3) | D22: Owed by deployers that are public authorities. A provider registers its own systems (Art. 49(1)), which here means the in-house attrition model.
B23: Annex III point 3, education and vocational training | C23: Annex III, 3 | D23: Covers education and vocational training institutions; an employer's course suggestions that do not feed promotion or pay are not in it.

Sheet Workers
A1: Telling the workers: the national rules each system triggers
A2: Row 5 gives the source. Under the AI Act itself (Art. 26(7)), see obligation O08 on the Obligations sheet.
A4: ID | B4: AI system | C4: Class | D4: W-IT1 IT | E4: W-IT2 IT | F4: W-DE1 DE | G4: W-DE2 DE | H4: W-DE3 DE | I4: W-DE4 DE | J4: W-ES1 ES | K4: W-PL1 PL
D5: D.lgs. 152/1997 art. 1-bis co. 1-6; L. 132/2025 art. 11 | E5: Statuto dei lavoratori, art. 4 | F5: BetrVG §90(1) Nr. 3, §90(2) | G5: BetrVG §87(1) Nr. 6 | H5: BetrVG §95(1); (2a) where AI helps draw them up | I5: BetrVG §80(3) | J5: Estatuto de los Trabajadores art. 64.4.d | K5: Kodeks pracy art. 22³ §4 with art. 22² §§6-10
A6: =Register!A5 | B6: =Register!B5 | C6: =Register!$W$5 | D6: =IF(AND(Register!$F$5="Yes",Register!$W$5<>"Prohibited",AND(Register!$J$5<>"Yes",Register!$R$5="Yes",OR(Register!$W$5="High-risk",Register!$S$5="Yes"))),"Yes","") | E6: =IF(AND(Register!$F$5="Yes",Register!$W$5<>"Prohibited",Register!$S$5="Yes"),"Yes","") | F6: =IF(AND(Register!$H$5="Yes",Register!$W$5<>"Prohibited",TRUE),"Yes","") | G6: =IF(AND(Register!$H$5="Yes",Register!$W$5<>"Prohibited",OR(Register!$S$5="Yes",AND(Register!$J$5<>"Yes",Register!$W$5="High-risk"))),"Yes","") | H6: =IF(AND(Register!$H$5="Yes",Register!$W$5<>"Prohibited",AND(Register!$M$5="4(a)",Register!$N$5="Yes",Register!$Q$5="Yes")),"Yes","") | I6: =IF(AND(Register!$H$5="Yes",Register!$W$5<>"Prohibited",TRUE),"Yes","") | J6: =IF(AND(Register!$I$5="Yes",Register!$W$5<>"Prohibited",Register!$W$5="High-risk"),"Yes","") | K6: =IF(AND(Register!$G$5="Yes",Register!$W$5<>"Prohibited",Register!$S$5="Yes"),"Yes","")
A7: =Register!A6 | B7: =Register!B6 | C7: =Register!$W$6 | D7: =IF(AND(Register!$F$6="Yes",Register!$W$6<>"Prohibited",AND(Register!$J$6<>"Yes",Register!$R$6="Yes",OR(Register!$W$6="High-risk",Register!$S$6="Yes"))),"Yes","") | E7: =IF(AND(Register!$F$6="Yes",Register!$W$6<>"Prohibited",Register!$S$6="Yes"),"Yes","") | F7: =IF(AND(Register!$H$6="Yes",Register!$W$6<>"Prohibited",TRUE),"Yes","") | G7: =IF(AND(Register!$H$6="Yes",Register!$W$6<>"Prohibited",OR(Register!$S$6="Yes",AND(Register!$J$6<>"Yes",Register!$W$6="High-risk"))),"Yes","") | H7: =IF(AND(Register!$H$6="Yes",Register!$W$6<>"Prohibited",AND(Register!$M$6="4(a)",Register!$N$6="Yes",Register!$Q$6="Yes")),"Yes","") | I7: =IF(AND(Register!$H$6="Yes",Register!$W$6<>"Prohibited",TRUE),"Yes","") | J7: =IF(AND(Register!$I$6="Yes",Register!$W$6<>"Prohibited",Register!$W$6="High-risk"),"Yes","") | K7: =IF(AND(Register!$G$6="Yes",Register!$W$6<>"Prohibited",Register!$S$6="Yes"),"Yes","")
A8: =Register!A7 | B8: =Register!B7 | C8: =Register!$W$7 | D8: =IF(AND(Register!$F$7="Yes",Register!$W$7<>"Prohibited",AND(Register!$J$7<>"Yes",Register!$R$7="Yes",OR(Register!$W$7="High-risk",Register!$S$7="Yes"))),"Yes","") | E8: =IF(AND(Register!$F$7="Yes",Register!$W$7<>"Prohibited",Register!$S$7="Yes"),"Yes","") | F8: =IF(AND(Register!$H$7="Yes",Register!$W$7<>"Prohibited",TRUE),"Yes","") | G8: =IF(AND(Register!$H$7="Yes",Register!$W$7<>"Prohibited",OR(Register!$S$7="Yes",AND(Register!$J$7<>"Yes",Register!$W$7="High-risk"))),"Yes","") | H8: =IF(AND(Register!$H$7="Yes",Register!$W$7<>"Prohibited",AND(Register!$M$7="4(a)",Register!$N$7="Yes",Register!$Q$7="Yes")),"Yes","") | I8: =IF(AND(Register!$H$7="Yes",Register!$W$7<>"Prohibited",TRUE),"Yes","") | J8: =IF(AND(Register!$I$7="Yes",Register!$W$7<>"Prohibited",Register!$W$7="High-risk"),"Yes","") | K8: =IF(AND(Register!$G$7="Yes",Register!$W$7<>"Prohibited",Register!$S$7="Yes"),"Yes","")
A9: =Register!A8 | B9: =Register!B8 | C9: =Register!$W$8 | D9: =IF(AND(Register!$F$8="Yes",Register!$W$8<>"Prohibited",AND(Register!$J$8<>"Yes",Register!$R$8="Yes",OR(Register!$W$8="High-risk",Register!$S$8="Yes"))),"Yes","") | E9: =IF(AND(Register!$F$8="Yes",Register!$W$8<>"Prohibited",Register!$S$8="Yes"),"Yes","") | F9: =IF(AND(Register!$H$8="Yes",Register!$W$8<>"Prohibited",TRUE),"Yes","") | G9: =IF(AND(Register!$H$8="Yes",Register!$W$8<>"Prohibited",OR(Register!$S$8="Yes",AND(Register!$J$8<>"Yes",Register!$W$8="High-risk"))),"Yes","") | H9: =IF(AND(Register!$H$8="Yes",Register!$W$8<>"Prohibited",AND(Register!$M$8="4(a)",Register!$N$8="Yes",Register!$Q$8="Yes")),"Yes","") | I9: =IF(AND(Register!$H$8="Yes",Register!$W$8<>"Prohibited",TRUE),"Yes","") | J9: =IF(AND(Register!$I$8="Yes",Register!$W$8<>"Prohibited",Register!$W$8="High-risk"),"Yes","") | K9: =IF(AND(Register!$G$8="Yes",Register!$W$8<>"Prohibited",Register!$S$8="Yes"),"Yes","")
A10: =Register!A9 | B10: =Register!B9 | C10: =Register!$W$9 | D10: =IF(AND(Register!$F$9="Yes",Register!$W$9<>"Prohibited",AND(Register!$J$9<>"Yes",Register!$R$9="Yes",OR(Register!$W$9="High-risk",Register!$S$9="Yes"))),"Yes","") | E10: =IF(AND(Register!$F$9="Yes",Register!$W$9<>"Prohibited",Register!$S$9="Yes"),"Yes","") | F10: =IF(AND(Register!$H$9="Yes",Register!$W$9<>"Prohibited",TRUE),"Yes","") | G10: =IF(AND(Register!$H$9="Yes",Register!$W$9<>"Prohibited",OR(Register!$S$9="Yes",AND(Register!$J$9<>"Yes",Register!$W$9="High-risk"))),"Yes","") | H10: =IF(AND(Register!$H$9="Yes",Register!$W$9<>"Prohibited",AND(Register!$M$9="4(a)",Register!$N$9="Yes",Register!$Q$9="Yes")),"Yes","") | I10: =IF(AND(Register!$H$9="Yes",Register!$W$9<>"Prohibited",TRUE),"Yes","") | J10: =IF(AND(Register!$I$9="Yes",Register!$W$9<>"Prohibited",Register!$W$9="High-risk"),"Yes","") | K10: =IF(AND(Register!$G$9="Yes",Register!$W$9<>"Prohibited",Register!$S$9="Yes"),"Yes","")
A11: =Register!A10 | B11: =Register!B10 | C11: =Register!$W$10 | D11: =IF(AND(Register!$F$10="Yes",Register!$W$10<>"Prohibited",AND(Register!$J$10<>"Yes",Register!$R$10="Yes",OR(Register!$W$10="High-risk",Register!$S$10="Yes"))),"Yes","") | E11: =IF(AND(Register!$F$10="Yes",Register!$W$10<>"Prohibited",Register!$S$10="Yes"),"Yes","") | F11: =IF(AND(Register!$H$10="Yes",Register!$W$10<>"Prohibited",TRUE),"Yes","") | G11: =IF(AND(Register!$H$10="Yes",Register!$W$10<>"Prohibited",OR(Register!$S$10="Yes",AND(Register!$J$10<>"Yes",Register!$W$10="High-risk"))),"Yes","") | H11: =IF(AND(Register!$H$10="Yes",Register!$W$10<>"Prohibited",AND(Register!$M$10="4(a)",Register!$N$10="Yes",Register!$Q$10="Yes")),"Yes","") | I11: =IF(AND(Register!$H$10="Yes",Register!$W$10<>"Prohibited",TRUE),"Yes","") | J11: =IF(AND(Register!$I$10="Yes",Register!$W$10<>"Prohibited",Register!$W$10="High-risk"),"Yes","") | K11: =IF(AND(Register!$G$10="Yes",Register!$W$10<>"Prohibited",Register!$S$10="Yes"),"Yes","")
A12: =Register!A11 | B12: =Register!B11 | C12: =Register!$W$11 | D12: =IF(AND(Register!$F$11="Yes",Register!$W$11<>"Prohibited",AND(Register!$J$11<>"Yes",Register!$R$11="Yes",OR(Register!$W$11="High-risk",Register!$S$11="Yes"))),"Yes","") | E12: =IF(AND(Register!$F$11="Yes",Register!$W$11<>"Prohibited",Register!$S$11="Yes"),"Yes","") | F12: =IF(AND(Register!$H$11="Yes",Register!$W$11<>"Prohibited",TRUE),"Yes","") | G12: =IF(AND(Register!$H$11="Yes",Register!$W$11<>"Prohibited",OR(Register!$S$11="Yes",AND(Register!$J$11<>"Yes",Register!$W$11="High-risk"))),"Yes","") | H12: =IF(AND(Register!$H$11="Yes",Register!$W$11<>"Prohibited",AND(Register!$M$11="4(a)",Register!$N$11="Yes",Register!$Q$11="Yes")),"Yes","") | I12: =IF(AND(Register!$H$11="Yes",Register!$W$11<>"Prohibited",TRUE),"Yes","") | J12: =IF(AND(Register!$I$11="Yes",Register!$W$11<>"Prohibited",Register!$W$11="High-risk"),"Yes","") | K12: =IF(AND(Register!$G$11="Yes",Register!$W$11<>"Prohibited",Register!$S$11="Yes"),"Yes","")
A13: =Register!A12 | B13: =Register!B12 | C13: =Register!$W$12 | D13: =IF(AND(Register!$F$12="Yes",Register!$W$12<>"Prohibited",AND(Register!$J$12<>"Yes",Register!$R$12="Yes",OR(Register!$W$12="High-risk",Register!$S$12="Yes"))),"Yes","") | E13: =IF(AND(Register!$F$12="Yes",Register!$W$12<>"Prohibited",Register!$S$12="Yes"),"Yes","") | F13: =IF(AND(Register!$H$12="Yes",Register!$W$12<>"Prohibited",TRUE),"Yes","") | G13: =IF(AND(Register!$H$12="Yes",Register!$W$12<>"Prohibited",OR(Register!$S$12="Yes",AND(Register!$J$12<>"Yes",Register!$W$12="High-risk"))),"Yes","") | H13: =IF(AND(Register!$H$12="Yes",Register!$W$12<>"Prohibited",AND(Register!$M$12="4(a)",Register!$N$12="Yes",Register!$Q$12="Yes")),"Yes","") | I13: =IF(AND(Register!$H$12="Yes",Register!$W$12<>"Prohibited",TRUE),"Yes","") | J13: =IF(AND(Register!$I$12="Yes",Register!$W$12<>"Prohibited",Register!$W$12="High-risk"),"Yes","") | K13: =IF(AND(Register!$G$12="Yes",Register!$W$12<>"Prohibited",Register!$S$12="Yes"),"Yes","")
A14: =Register!A13 | B14: =Register!B13 | C14: =Register!$W$13 | D14: =IF(AND(Register!$F$13="Yes",Register!$W$13<>"Prohibited",AND(Register!$J$13<>"Yes",Register!$R$13="Yes",OR(Register!$W$13="High-risk",Register!$S$13="Yes"))),"Yes","") | E14: =IF(AND(Register!$F$13="Yes",Register!$W$13<>"Prohibited",Register!$S$13="Yes"),"Yes","") | F14: =IF(AND(Register!$H$13="Yes",Register!$W$13<>"Prohibited",TRUE),"Yes","") | G14: =IF(AND(Register!$H$13="Yes",Register!$W$13<>"Prohibited",OR(Register!$S$13="Yes",AND(Register!$J$13<>"Yes",Register!$W$13="High-risk"))),"Yes","") | H14: =IF(AND(Register!$H$13="Yes",Register!$W$13<>"Prohibited",AND(Register!$M$13="4(a)",Register!$N$13="Yes",Register!$Q$13="Yes")),"Yes","") | I14: =IF(AND(Register!$H$13="Yes",Register!$W$13<>"Prohibited",TRUE),"Yes","") | J14: =IF(AND(Register!$I$13="Yes",Register!$W$13<>"Prohibited",Register!$W$13="High-risk"),"Yes","") | K14: =IF(AND(Register!$G$13="Yes",Register!$W$13<>"Prohibited",Register!$S$13="Yes"),"Yes","")
A15: =Register!A14 | B15: =Register!B14 | C15: =Register!$W$14 | D15: =IF(AND(Register!$F$14="Yes",Register!$W$14<>"Prohibited",AND(Register!$J$14<>"Yes",Register!$R$14="Yes",OR(Register!$W$14="High-risk",Register!$S$14="Yes"))),"Yes","") | E15: =IF(AND(Register!$F$14="Yes",Register!$W$14<>"Prohibited",Register!$S$14="Yes"),"Yes","") | F15: =IF(AND(Register!$H$14="Yes",Register!$W$14<>"Prohibited",TRUE),"Yes","") | G15: =IF(AND(Register!$H$14="Yes",Register!$W$14<>"Prohibited",OR(Register!$S$14="Yes",AND(Register!$J$14<>"Yes",Register!$W$14="High-risk"))),"Yes","") | H15: =IF(AND(Register!$H$14="Yes",Register!$W$14<>"Prohibited",AND(Register!$M$14="4(a)",Register!$N$14="Yes",Register!$Q$14="Yes")),"Yes","") | I15: =IF(AND(Register!$H$14="Yes",Register!$W$14<>"Prohibited",TRUE),"Yes","") | J15: =IF(AND(Register!$I$14="Yes",Register!$W$14<>"Prohibited",Register!$W$14="High-risk"),"Yes","") | K15: =IF(AND(Register!$G$14="Yes",Register!$W$14<>"Prohibited",Register!$S$14="Yes"),"Yes","")
A16: =Register!A15 | B16: =Register!B15 | C16: =Register!$W$15 | D16: =IF(AND(Register!$F$15="Yes",Register!$W$15<>"Prohibited",AND(Register!$J$15<>"Yes",Register!$R$15="Yes",OR(Register!$W$15="High-risk",Register!$S$15="Yes"))),"Yes","") | E16: =IF(AND(Register!$F$15="Yes",Register!$W$15<>"Prohibited",Register!$S$15="Yes"),"Yes","") | F16: =IF(AND(Register!$H$15="Yes",Register!$W$15<>"Prohibited",TRUE),"Yes","") | G16: =IF(AND(Register!$H$15="Yes",Register!$W$15<>"Prohibited",OR(Register!$S$15="Yes",AND(Register!$J$15<>"Yes",Register!$W$15="High-risk"))),"Yes","") | H16: =IF(AND(Register!$H$15="Yes",Register!$W$15<>"Prohibited",AND(Register!$M$15="4(a)",Register!$N$15="Yes",Register!$Q$15="Yes")),"Yes","") | I16: =IF(AND(Register!$H$15="Yes",Register!$W$15<>"Prohibited",TRUE),"Yes","") | J16: =IF(AND(Register!$I$15="Yes",Register!$W$15<>"Prohibited",Register!$W$15="High-risk"),"Yes","") | K16: =IF(AND(Register!$G$15="Yes",Register!$W$15<>"Prohibited",Register!$S$15="Yes"),"Yes","")
A17: =Register!A16 | B17: =Register!B16 | C17: =Register!$W$16 | D17: =IF(AND(Register!$F$16="Yes",Register!$W$16<>"Prohibited",AND(Register!$J$16<>"Yes",Register!$R$16="Yes",OR(Register!$W$16="High-risk",Register!$S$16="Yes"))),"Yes","") | E17: =IF(AND(Register!$F$16="Yes",Register!$W$16<>"Prohibited",Register!$S$16="Yes"),"Yes","") | F17: =IF(AND(Register!$H$16="Yes",Register!$W$16<>"Prohibited",TRUE),"Yes","") | G17: =IF(AND(Register!$H$16="Yes",Register!$W$16<>"Prohibited",OR(Register!$S$16="Yes",AND(Register!$J$16<>"Yes",Register!$W$16="High-risk"))),"Yes","") | H17: =IF(AND(Register!$H$16="Yes",Register!$W$16<>"Prohibited",AND(Register!$M$16="4(a)",Register!$N$16="Yes",Register!$Q$16="Yes")),"Yes","") | I17: =IF(AND(Register!$H$16="Yes",Register!$W$16<>"Prohibited",TRUE),"Yes","") | J17: =IF(AND(Register!$I$16="Yes",Register!$W$16<>"Prohibited",Register!$W$16="High-risk"),"Yes","") | K17: =IF(AND(Register!$G$16="Yes",Register!$W$16<>"Prohibited",Register!$S$16="Yes"),"Yes","")
B18: Systems | D18: =COUNTIF(D6:D17,"Yes") | E18: =COUNTIF(E6:E17,"Yes") | F18: =COUNTIF(F6:F17,"Yes") | G18: =COUNTIF(G6:G17,"Yes") | H18: =COUNTIF(H6:H17,"Yes") | I18: =COUNTIF(I6:I17,"Yes") | J18: =COUNTIF(J6:J17,"Yes") | K18: =COUNTIF(K6:K17,"Yes")
A20: Rule | C20: Country | D20: What it asks | G20: When
A21: W-IT1 | B21: Information on fully automated decision or monitoring systems | C21: IT · Milan | D21: In writing, to each worker and to the union representatives (RSA/RSU): the aspects of the job affected, purposes, logic and functioning, data and main parameters, control and correction measures, accuracy, robustness and cybersecurity, possible discriminatory effects; in a structured, machine-readable format | G21: Before work starts; at least 24 hours before any change to that information
A22: W-IT2 | B22: Agreement or authorisation for tools that allow remote monitoring | C22: IT · Milan | D22: Only for organisational and production needs, safety or protection of company assets, and with an agreement with the union representatives or, failing that, authorisation by the labour inspectorate; tools used to do the work and attendance records are exempt; the data can be used only with adequate information to workers | G22: Before the tool is installed
A23: W-DE1 | B23: Information and consultation on planned AI in work procedures | C23: DE · Munich | D23: Inform the works council with the documents, and consult it while its views can still change the plan | G23: At the planning stage
A24: W-DE2 | B24: Co-determination on technical devices able to monitor conduct or performance | C24: DE · Munich | D24: A works agreement; without it the system cannot lawfully be used. Courts read 'able to' broadly, so systems that log identifiable use may also need one | G24: Before introduction
A25: W-DE3 | B25: Co-determination on selection guidelines | C25: DE · Munich | D25: Works council consent to the selection criteria the system applies | G25: Before use in hiring, transfer or dismissal decisions
A26: W-DE4 | B26: An expert for the works council, deemed necessary for AI | C26: DE · Munich | D26: An expert, agreed with the employer as to person, subject and cost; for AI its necessity is presumed | G26: When the works council assesses the system
A27: W-ES1 | B27: Information on the parameters of algorithms affecting work | C27: ES · Barcelona | D27: The parameters, rules and instructions the system is based on, to the works council | G27: With the periodicity that applies; before use is the prudent reading
A28: W-PL1 | B28: Notice of monitoring other than video | C28: PL · Kraków | D28: Allowed only where needed for full use of working time and proper use of work tools; purpose, scope and method in the workplace rules | G28: At least two weeks before it starts; new hires in writing before they start

Sheet Timeline
A1: Timeline: every obligation in date order
A2: In force means the date has passed at the assessment date in Settings.
A4: Key | B4: Obligation | C4: Article | D4: Applies from | E4: Systems | F4: Days from now | G4: Status
A5: O01 | B5: AI literacy of the staff who operate or use it | C5: Art. 4 | D5: =Settings!$C$5 | E5: =Obligations!D18 | F5: =D5-Settings!$C$4 | G5: =IF(F5<=0,"In force","Ahead")
A6: O02 | B6: Stop the prohibited use | C6: Art. 5(1)(f) | D6: =Settings!$C$5 | E6: =Obligations!E18 | F6: =D6-Settings!$C$4 | G6: =IF(F6<=0,"In force","Ahead")
A7: O03 | B7: People told they are talking to an AI: the supplier's duty, checked by the employer | C7: Art. 50(1) | D7: =Settings!$C$6 | E7: =Obligations!F18 | F7: =D7-Settings!$C$4 | G7: =IF(F7<=0,"In force","Ahead")
A8: O04 | B8: Use as instructed, with named human oversight | C8: Art. 26(1)-(2) | D8: =Settings!$C$7 | E8: =Obligations!G18 | F8: =D8-Settings!$C$4 | G8: =IF(F8<=0,"In force","Ahead")
A9: O05 | B9: Input data relevant and representative | C9: Art. 26(4) | D9: =Settings!$C$7 | E9: =Obligations!H18 | F9: =D9-Settings!$C$4 | G9: =IF(F9<=0,"In force","Ahead")
A10: O06 | B10: Monitor; report risks and serious incidents; suspend | C10: Art. 26(5) | D10: =Settings!$C$7 | E10: =Obligations!I18 | F10: =D10-Settings!$C$4 | G10: =IF(F10<=0,"In force","Ahead")
A11: O07 | B11: Keep the logs for at least six months | C11: Art. 26(6) | D11: =Settings!$C$7 | E11: =Obligations!J18 | F11: =D11-Settings!$C$4 | G11: =IF(F11<=0,"In force","Ahead")
A12: O08 | B12: Tell workers' representatives and affected workers before use | C12: Art. 26(7) | D12: =Settings!$C$7 | E12: =Obligations!K18 | F12: =D12-Settings!$C$4 | G12: =IF(F12<=0,"In force","Ahead")
A13: O09 | B13: Data protection impact assessment built on the provider's information | C13: Art. 26(9); GDPR Art. 35 | D13: =Settings!$C$7 | E13: =Obligations!L18 | F13: =D13-Settings!$C$4 | G13: =IF(F13<=0,"In force","Ahead")
A14: O10 | B14: Tell the people decisions are made about | C14: Art. 26(11) | D14: =Settings!$C$7 | E14: =Obligations!M18 | F14: =D14-Settings!$C$4 | G14: =IF(F14<=0,"In force","Ahead")
A15: O11 | B15: Explain a decision on request | C15: Art. 86 | D15: =Settings!$C$7 | E15: =Obligations!N18 | F15: =D15-Settings!$C$4 | G15: =IF(F15<=0,"In force","Ahead")
A16: O12 | B16: Provider duties for a system built in-house | C16: Art. 3(3), 16 | D16: =Settings!$C$7 | E16: =Obligations!O18 | F16: =D16-Settings!$C$4 | G16: =IF(F16<=0,"In force","Ahead")
A17: O13 | B17: Not-high-risk assessment documented | C17: Art. 6(4) | D17: =Settings!$C$7 | E17: =Obligations!P18 | F17: =D17-Settings!$C$4 | G17: =IF(F17<=0,"In force","Ahead")
B19: Days to 2 December 2027, when the high-risk duties start | F19: =Settings!$C$7-Settings!$C$4

Sheet Headcount
A1: Headcount by employer and department
A2: Workers active on 30 June 2026, from the payroll extract of pay-transparency-readiness-kit (commit 0bfb9c9).
A4: Employer | B4: Department | C4: Workers
A5: DE | B5: Customer Service | C5: 209
A6: DE | B6: Finance | C6: 79
A7: DE | B7: HR | C7: 73
A8: DE | B8: Operations | C8: 185
A9: DE | B9: Sales | C9: 92
A10: DE | B10: Tech | C10: 103
A11: ES | B11: Customer Service | C11: 149
A12: ES | B12: Finance | C12: 44
A13: ES | B13: HR | C13: 43
A14: ES | B14: Operations | C14: 112
A15: ES | B15: Sales | C15: 71
A16: ES | B16: Tech | C16: 74
... A28: PL | B28: Tech | C28: 194
B29: Total | C29: =SUM(C5:C28)

Sheet Settings
A1: Settings
A2: The dates the register runs on. Blue cells can be changed.
B4: Date of this assessment | C4: 46319 | D4: Days to each deadline count from here.
B5: Articles 4 and 5 apply from | C5: 45690 | D5: Art. 113(a).
B6: Article 50 and the rest apply from | C6: 46236 | D6: Art. 113, first paragraph.
B7: Articles 6 to 27 apply to Annex III systems from | C7: 46723 | D7: Art. 113(c)(i) as amended by Regulation (EU) 2026/1744 (was 2 August 2026).

Sheet Reconciliation
A1: Reconciliation: workbook formulas against the Python register
A2: Column D was written by src/build_workbook.py from the Python results; column E is the live formula.
B3: =IF(COUNTIF(G7:G336,"Yes")=COUNTA(B7:B336),"All "&COUNTA(B7:B336)&" checks match",(COUNTA(B7:B336)-COUNTIF(G7:G336,"Yes"))&" of "&COUNTA(B7:B336)&" checks do not match")
A6: Area | B6: Item | D6: Python value | E6: Workbook value | F6: Difference | G6: Match
A7: Headcount | B7: Workers in all four employers | D7: 3443 | E7: =Headcount!C29 | F7: =IF(AND(ISNUMBER(D7),ISNUMBER(E7)),E7-D7,"") | G7: =IFERROR(IF(AND(D7="",E7=""),"Yes",IF(AND(ISNUMBER(D7),ISNUMBER(E7)),IF(ABS(E7-D7)<=1E-9*MAX(1,ABS(D7)),"Yes","No"),IF(EXACT(D7,E7),"Yes","No"))),"No")
A8: Register | B8: S01 CV screening and ranking: class | D8: High-risk | E8: =Register!W5 | F8: =IF(AND(ISNUMBER(D8),ISNUMBER(E8)),E8-D8,"") | G8: =IFERROR(IF(AND(D8="",E8=""),"Yes",IF(AND(ISNUMBER(D8),ISNUMBER(E8)),IF(ABS(E8-D8)<=1E-9*MAX(1,ABS(D8)),"Yes","No"),IF(EXACT(D8,E8),"Yes","No"))),"No")
A9: Register | B9: S01 CV screening and ranking: role | D9: Deployer | E9: =Register!X5 | F9: =IF(AND(ISNUMBER(D9),ISNUMBER(E9)),E9-D9,"") | G9: =IFERROR(IF(AND(D9="",E9=""),"Yes",IF(AND(ISNUMBER(D9),ISNUMBER(E9)),IF(ABS(E9-D9)<=1E-9*MAX(1,ABS(D9)),"Yes","No"),IF(EXACT(D9,E9),"Yes","No"))),"No")
A10: Register | B10: S01 CV screening and ranking: high-risk timing | D10: At its next significant design change | E10: =Register!Y5 | F10: =IF(AND(ISNUMBER(D10),ISNUMBER(E10)),E10-D10,"") | G10: =IFERROR(IF(AND(D10="",E10=""),"Yes",IF(AND(ISNUMBER(D10),ISNUMBER(E10)),IF(ABS(E10-D10)<=1E-9*MAX(1,ABS(D10)),"Yes","No"),IF(EXACT(D10,E10),"Yes","No"))),"No")
A11: Register | B11: S01 CV screening and ranking: workers in scope | D11: 3443 | E11: =Register!V5 | F11: =IF(AND(ISNUMBER(D11),ISNUMBER(E11)),E11-D11,"") | G11: =IFERROR(IF(AND(D11="",E11=""),"Yes",IF(AND(ISNUMBER(D11),ISNUMBER(E11)),IF(ABS(E11-D11)<=1E-9*MAX(1,ABS(D11)),"Yes","No"),IF(EXACT(D11,E11),"Yes","No"))),"No")
A12: Register | B12: S02 Targeted job advertising: class | D12: High-risk | E12: =Register!W6 | F12: =IF(AND(ISNUMBER(D12),ISNUMBER(E12)),E12-D12,"") | G12: =IFERROR(IF(AND(D12="",E12=""),"Yes",IF(AND(ISNUMBER(D12),ISNUMBER(E12)),IF(ABS(E12-D12)<=1E-9*MAX(1,ABS(D12)),"Yes","No"),IF(EXACT(D12,E12),"Yes","No"))),"No")
A13: Register | B13: S02 Targeted job advertising: role | D13: Deployer | E13: =Register!X6 | F13: =IF(AND(ISNUMBER(D13),ISNUMBER(E13)),E13-D13,"") | G13: =IFERROR(IF(AND(D13="",E13=""),"Yes",IF(AND(ISNUMBER(D13),ISNUMBER(E13)),IF(ABS(E13-D13)<=1E-9*MAX(1,ABS(D13)),"Yes","No"),IF(EXACT(D13,E13),"Yes","No"))),"No")
A14: Register | B14: S02 Targeted job advertising: high-risk timing | D14: At its next significant design change | E14: =Register!Y6 | F14: =IF(AND(ISNUMBER(D14),ISNUMBER(E14)),E14-D14,"") | G14: =IFERROR(IF(AND(D14="",E14=""),"Yes",IF(AND(ISNUMBER(D14),ISNUMBER(E14)),IF(ABS(E14-D14)<=1E-9*MAX(1,ABS(D14)),"Yes","No"),IF(EXACT(D14,E14),"Yes","No"))),"No")
A15: Register | B15: S02 Targeted job advertising: workers in scope | D15: 3443 | E15: =Register!V6 | F15: =IF(AND(ISNUMBER(D15),ISNUMBER(E15)),E15-D15,"") | G15: =IFERROR(IF(AND(D15="",E15=""),"Yes",IF(AND(ISNUMBER(D15),ISNUMBER(E15)),IF(ABS(E15-D15)<=1E-9*MAX(1,ABS(D15)),"Yes","No"),IF(EXACT(D15,E15),"Yes","No"))),"No")
A16: Register | B16: S03 Video interview analysis: class | D16: Prohibited | E16: =Register!W7 | F16: =IF(AND(ISNUMBER(D16),ISNUMBER(E16)),E16-D16,"") | G16: =IFERROR(IF(AND(D16="",E16=""),"Yes",IF(AND(ISNUMBER(D16),ISNUMBER(E16)),IF(ABS(E16-D16)<=1E-9*MAX(1,ABS(D16)),"Yes","No"),IF(EXACT(D16,E16),"Yes","No"))),"No")
A17: Register | B17: S03 Video interview analysis: role | D17: Deployer | E17: =Register!X7 | F17: =IF(AND(ISNUMBER(D17),ISNUMBER(E17)),E17-D17,"") | G17: =IFERROR(IF(AND(D17="",E17=""),"Yes",IF(AND(ISNUMBER(D17),ISNUMBER(E17)),IF(ABS(E17-D17)<=1E-9*MAX(1,ABS(D17)),"Yes","No"),IF(EXACT(D17,E17),"Yes","No"))),"No")
A18: Register | B18: S03 Video interview analysis: high-risk timing | E18: =Register!Y7 | F18: =IF(AND(ISNUMBER(D18),ISNUMBER(E18)),E18-D18,"") | G18: =IFERROR(IF(AND(D18="",E18=""),"Yes",IF(AND(ISNUMBER(D18),ISNUMBER(E18)),IF(ABS(E18-D18)<=1E-9*MAX(1,ABS(D18)),"Yes","No"),IF(EXACT(D18,E18),"Yes","No"))),"No")
A19: Register | B19: S03 Video interview analysis: workers in scope | D19: 493 | E19: =Register!V7 | F19: =IF(AND(ISNUMBER(D19),ISNUMBER(E19)),E19-D19,"") | G19: =IFERROR(IF(AND(D19="",E19=""),"Yes",IF(AND(ISNUMBER(D19),ISNUMBER(E19)),IF(ABS(E19-D19)<=1E-9*MAX(1,ABS(D19)),"Yes","No"),IF(EXACT(D19,E19),"Yes","No"))),"No")
A20: Register | B20: S04 Interview scheduling assistant: class | D20: Not high-risk (Art. 6(3)) | E20: =Register!W8 | F20: =IF(AND(ISNUMBER(D20),ISNUMBER(E20)),E20-D20,"") | G20: =IFERROR(IF(AND(D20="",E20=""),"Yes",IF(AND(ISNUMBER(D20),ISNUMBER(E20)),IF(ABS(E20-D20)<=1E-9*MAX(1,ABS(D20)),"Yes","No"),IF(EXACT(D20,E20),"Yes","No"))),"No")
A21: Register | B21: S04 Interview scheduling assistant: role | D21: Deployer | E21: =Register!X8 | F21: =IF(AND(ISNUMBER(D21),ISNUMBER(E21)),E21-D21,"") | G21: =IFERROR(IF(AND(D21="",E21=""),"Yes",IF(AND(ISNUMBER(D21),ISNUMBER(E21)),IF(ABS(E21-D21)<=1E-9*MAX(1,ABS(D21)),"Yes","No"),IF(EXACT(D21,E21),"Yes","No"))),"No")
A22: Register | B22: S04 Interview scheduling assistant: high-risk timing | E22: =Register!Y8 | F22: =IF(AND(ISNUMBER(D22),ISNUMBER(E22)),E22-D22,"") | G22: =IFERROR(IF(AND(D22="",E22=""),"Yes",IF(AND(ISNUMBER(D22),ISNUMBER(E22)),IF(ABS(E22-D22)<=1E-9*MAX(1,ABS(D22)),"Yes","No"),IF(EXACT(D22,E22),"Yes","No"))),"No")
A23: Register | B23: S04 Interview scheduling assistant: workers in scope | D23: 3443 | E23: =Register!V8 | F23: =IF(AND(ISNUMBER(D23),ISNUMBER(E23)),E23-D23,"") | G23: =IFERROR(IF(AND(D23="",E23=""),"Yes",IF(AND(ISNUMBER(D23),ISNUMBER(E23)),IF(ABS(E23-D23)<=1E-9*MAX(1,ABS(D23)),"Yes","No"),IF(EXACT(D23,E23),"Yes","No"))),"No")
A24: Register | B24: S05 Customer service performance analytics: class | D24: High-risk | E24: =Register!W9 | F24: =IF(AND(ISNUMBER(D24),ISNUMBER(E24)),E24-D24,"") | G24: =IFERROR(IF(AND(D24="",E24=""),"Yes",IF(AND(ISNUMBER(D24),ISNUMBER(E24)),IF(ABS(E24-D24)<=1E-9*MAX(1,ABS(D24)),"Yes","No"),IF(EXACT(D24,E24),"Yes","No"))),"No")
A25: Register | B25: S05 Customer service performance analytics: role | D25: Deployer | E25: =Register!X9 | F25: =IF(AND(ISNUMBER(D25),ISNUMBER(E25)),E25-D25,"") | G25: =IFERROR(IF(AND(D25="",E25=""),"Yes",IF(AND(ISNUMBER(D25),ISNUMBER(E25)),IF(ABS(E25-D25)<=1E-9*MAX(1,ABS(D25)),"Yes","No"),IF(EXACT(D25,E25),"Yes","No"))),"No")
A26: Register | B26: S05 Customer service performance analytics: high-risk timing | D26: At its next significant design change | E26: =Register!Y9 | F26: =IF(AND(ISNUMBER(D26),ISNUMBER(E26)),E26-D26,"") | G26: =IFERROR(IF(AND(D26="",E26=""),"Yes",IF(AND(ISNUMBER(D26),ISNUMBER(E26)),IF(ABS(E26-D26)<=1E-9*MAX(1,ABS(D26)),"Yes","No"),IF(EXACT(D26,E26),"Yes","No"))),"No")
A27: Register | B27: S05 Customer service performance analytics: workers in scope | D27: 996 | E27: =Register!V9 | F27: =IF(AND(ISNUMBER(D27),ISNUMBER(E27)),E27-D27,"") | G27: =IFERROR(IF(AND(D27="",E27=""),"Yes",IF(AND(ISNUMBER(D27),ISNUMBER(E27)),IF(ABS(E27-D27)<=1E-9*MAX(1,ABS(D27)),"Yes","No"),IF(EXACT(D27,E27),"Yes","No"))),"No")
A28: Register | B28: S06 Shift scheduling optimiser: class | D28: High-risk | E28: =Register!W10 | F28: =IF(AND(ISNUMBER(D28),ISNUMBER(E28)),E28-D28,"") | G28: =IFERROR(IF(AND(D28="",E28=""),"Yes",IF(AND(ISNUMBER(D28),ISNUMBER(E28)),IF(ABS(E28-D28)<=1E-9*MAX(1,ABS(D28)),"Yes","No"),IF(EXACT(D28,E28),"Yes","No"))),"No")
A29: Register | B29: S06 Shift scheduling optimiser: role | D29: Deployer | E29: =Register!X10 | F29: =IF(AND(ISNUMBER(D29),ISNUMBER(E29)),E29-D29,"") | G29: =IFERROR(IF(AND(D29="",E29=""),"Yes",IF(AND(ISNUMBER(D29),ISNUMBER(E29)),IF(ABS(E29-D29)<=1E-9*MAX(1,ABS(D29)),"Yes","No"),IF(EXACT(D29,E29),"Yes","No"))),"No")
A30: Register | B30: S06 Shift scheduling optimiser: high-risk timing | D30: At its next significant design change | E30: =Register!Y10 | F30: =IF(AND(ISNUMBER(D30),ISNUMBER(E30)),E30-D30,"") | G30: =IFERROR(IF(AND(D30="",E30=""),"Yes",IF(AND(ISNUMBER(D30),ISNUMBER(E30)),IF(ABS(E30-D30)<=1E-9*MAX(1,ABS(D30)),"Yes","No"),IF(EXACT(D30,E30),"Yes","No"))),"No")
A31: Register | B31: S06 Shift scheduling optimiser: workers in scope | D31: 851 | E31: =Register!V10 | F31: =IF(AND(ISNUMBER(D31),ISNUMBER(E31)),E31-D31,"") | G31: =IFERROR(IF(AND(D31="",E31=""),"Yes",IF(AND(ISNUMBER(D31),ISNUMBER(E31)),IF(ABS(E31-D31)<=1E-9*MAX(1,ABS(D31)),"Yes","No"),IF(EXACT(D31,E31),"Yes","No"))),"No")
A32: Register | B32: S07 Attrition-risk model: class | D32: High-risk | E32: =Register!W11 | F32: =IF(AND(ISNUMBER(D32),ISNUMBER(E32)),E32-D32,"") | G32: =IFERROR(IF(AND(D32="",E32=""),"Yes",IF(AND(ISNUMBER(D32),ISNUMBER(E32)),IF(ABS(E32-D32)<=1E-9*MAX(1,ABS(D32)),"Yes","No"),IF(EXACT(D32,E32),"Yes","No"))),"No")
A33: Register | B33: S07 Attrition-risk model: role | D33: Provider and deployer | E33: =Register!X11 | F33: =IF(AND(ISNUMBER(D33),ISNUMBER(E33)),E33-D33,"") | G33: =IFERROR(IF(AND(D33="",E33=""),"Yes",IF(AND(ISNUMBER(D33),ISNUMBER(E33)),IF(ABS(E33-D33)<=1E-9*MAX(1,ABS(D33)),"Yes","No"),IF(EXACT(D33,E33),"Yes","No"))),"No")
A34: Register | B34: S07 Attrition-risk model: high-risk timing | D34: At its next significant design change | E34: =Register!Y11 | F34: =IF(AND(ISNUMBER(D34),ISNUMBER(E34)),E34-D34,"") | G34: =IFERROR(IF(AND(D34="",E34=""),"Yes",IF(AND(ISNUMBER(D34),ISNUMBER(E34)),IF(ABS(E34-D34)<=1E-9*MAX(1,ABS(D34)),"Yes","No"),IF(EXACT(D34,E34),"Yes","No"))),"No")
